Workbook
Name 제외사유: 조사불가목록!$A$1:$A$10

Sheet 조사현황표
B3: 구분 | C3: 시군구 | D3: 실제표본점 | E3: 수행 | F3: 제외 | G3: 잔량 | H3: 예비표본점 | I3: 예비잔량
B4: 서울 | C4: 강남구 | D4: 9 | E4: 9 | G4: =D4-E4 -> 0 | H4: 5 | I4: =H4-F4 -> 5
B5: 서울 | C5: 강동구 | D5: 6 | E5: 6 | G5: =D5-E5 -> 0 | H5: 3 | I5: =H5-F5 -> 3
B6: 서울 | C6: 강북구 | D6: 9 | G6: =D6-E6 -> 9 | H6: 5 | I6: =H6-F6 -> 5
B7: 서울 | C7: 관악구 | D7: 9 | G7: =D7-E7 -> 9 | H7: 5 | I7: =H7-F7 -> 5
B8: 서울 | C8: 광진구 | D8: 7 | E8: 7 | F8: 1 | G8: =D8-E8 -> 0 | H8: 4 | I8: =H8-F8 -> 3
B9: 서울 | C9: 구로구 | D9: 20 | G9: =D9-E9 -> 20 | H9: 10 | I9: =H9-F9 -> 10
B10: 서울 | C10: 금천구 | D10: 4 | G10: =D10-E10 -> 4 | H10: 2 | I10: =H10-F10 -> 2
B11: 서울 | C11: 노원구 | D11: 8 | E11: 8 | F11: 1 | G11: =D11-E11 -> 0 | H11: 4 | I11: =H11-F11 -> 3
B12: 서울 | C12: 도봉구 | D12: 7 | G12: =D12-E12 -> 7 | H12: 4 | I12: =H12-F12 -> 4
B13: 서울 | C13: 동대문구 | D13: 9 | G13: =D13-E13 -> 9 | H13: 5 | I13: =H13-F13 -> 5
B14: 서울 | C14: 동작구 | D14: 9 | G14: =D14-E14 -> 9 | H14: 5 | I14: =H14-F14 -> 5
B15: 서울 | C15: 마포구 | D15: 16 | G15: =D15-E15 -> 16 | H15: 8 | I15: =H15-F15 -> 8
B16: 서울 | C16: 서대문구 | D16: 4 | G16: =D16-E16 -> 4 | H16: 2 | I16: =H16-F16 -> 2
B17: 서울 | C17: 서울강서구 | D17: 19 | G17: =D17-E17 -> 19 | H17: 10 | I17: =H17-F17 -> 10
B18: 서울 | C18: 서울중구 | D18: 8 | G18: =D18-E18 -> 8 | H18: 4 | I18: =H18-F18 -> 4
B19: 서울 | C19: 서초구 | D19: 10 | E19: 10 | F19: 1 | G19: =D19-E19 -> 0 | H19: 5 | I19: =H19-F19 -> 4
B20: 서울 | C20: 성동구 | D20: 7 | E20: 6 | F20: 2 | G20: =D20-E20 -> 1 | H20: 6 | I20: =H20-F20 -> 4 | J20: 예비표본점개수(예비 추가2개 반영한 개수)
B21: 서울 | C21: 성북구 | D21: 5 | G21: =D21-E21 -> 5 | H21: 3 | I21: =H21-F21 -> 3
B22: 서울 | C22: 송파구 | D22: 9 | E22: 9 | F22: 1 | G22: =D22-E22 -> 0 | H22: 5 | I22: =H22-F22 -> 4
B23: 서울 | C23: 양천구 | D23: 8 | G23: =D23-E23 -> 8 | H23: 4 | I23: =H23-F23 -> 4
B24: 서울 | C24: 영등포구 | D24: 6 | G24: =D24-E24 -> 6 | H24: 3 | I24: =H24-F24 -> 3
B25: 서울 | C25: 용산구 | D25: 7 | G25: =D25-E25 -> 7 | H25: 4 | I25: =H25-F25 -> 4
B26: 서울 | C26: 은평구 | D26: 14 | G26: =D26-E26 -> 14 | H26: 7 | I26: =H26-F26 -> 7
B27: 서울 | C27: 종로구 | D27: 7 | G27: =D27-E27 -> 7 | H27: 4 | I27: =H27-F27 -> 4
B28: 서울 | C28: 중랑구 | D28: 8 | E28: 8 | G28: =D28-E28 -> 0 | H28: 4 | I28: =H28-F28 -> 4
B29: 부산 | C29: 금정구 | D29: 12 | G29: =D29-E29 -> 12 | H29: 6 | I29: =H29-F29 -> 6
B30: 부산 | C30: 기장군 | D30: 13 | G30: =D30-E30 -> 13 | H30: 7 | I30: =H30-F30 -> 7
B31: 부산 | C31: 동래구 | D31: 10 | G31: =D31-E31 -> 10 | H31: 5 | I31: =H31-F31 -> 5
B32: 부산 | C32: 부산강서구 | D32: 12 | E32: 12 | F32: 2 | G32: =D32-E32 -> 0 | H32: 6 | I32: =H32-F32 -> 4
B33: 부산 | C33: 부산남구 | D33: 24 | E33: 5 | G33: =D33-E33 -> 19 | H33: 12 | I33: =H33-F33 -> 12
B34: 부산 | C34: 부산동구 | D34: 9 | G34: =D34-E34 -> 9 | H34: 5 | I34: =H34-F34 -> 5
B35: 부산 | C35: 부산북구 | D35: 7 | E35: 7 | F35: 1 | G35: =D35-E35 -> 0 | H35: 4 | I35: =H35-F35 -> 3
B36: 부산 | C36: 부산서구 | D36: 11 | E36: 11 | G36: =D36-E36 -> 0 | H36: 6 | I36: =H36-F36 -> 6
B37: 부산 | C37: 부산중구 | D37: 11 | E37: 5 | G37: =D37-E37 -> 6 | H37: 6 | I37: =H37-F37 -> 6
B38: 부산 | C38: 부산진구 | D38: 3 | G38: =D38-E38 -> 3 | H38: 2 | I38: =H38-F38 -> 2
B39: 부산 | C39: 사상구 | D39: 8 | E39: 8 | F39: 1 | G39: =D39-E39 -> 0 | H39: 4 | I39: =H39-F39 -> 3
B40: 부산 | C40: 사하구 | D40: 7 | E40: 7 | F40: 2 | G40: =D40-E40 -> 0 | H40: 6 | I40: =H40-F40 -> 4 | J40: 예비표본점개수(예비 추가2개 반영한 개수)
B41: 부산 | C41: 수영구 | D41: 12 | G41: =D41-E41 -> 12 | H41: 6 | I41: =H41-F41 -> 6
B42: 부산 | C42: 연제구 | D42: 11 | G42: =D42-E42 -> 11 | H42: 6 | I42: =H42-F42 -> 6
...

Sheet 표본점목록
A1: 표본점번호 | B1: 유형 | C1: POINT_X | D1: POINT_Y | E1: 시도 | F1: 시군구 | G1: 읍면동 | H1: 주소 | I1: 조사가능불가 | J1: 조사번호 | K1: 표본점번호 | L1: EPSG4326 | M1: 표고 | N1: 구분 | O1: NFI지원팀
A2: 511121819730 | B2: 가로수 | C2: 1121800 | D2: 1973000 | E2: 강원특별자치도 | F2: 강릉시 | G2: 홍제동 | H2: 강원특별자치도 강릉시 홍제동 101-3 | I2: =VLOOKUP(A:A,조사결과표!B:G,7,0) -> #N/A | J2: 강릉시_필수_1 | K2: 511121819730 | L2: 37.7485371221, 128.8825443522 | M2: 27 | N2: 필수
A3: 511124019753 | B3: 가로수 | C3: 1124000 | D3: 1975300 | E3: 강원특별자치도 | F3: 강릉시 | G3: 포남동 | H3: 강원특별자치도 강릉시 포남동 1242-1 | I3: =VLOOKUP(A:A,조사결과표!B:G,7,0) -> #N/A | J3: 강릉시_필수_2 | K3: 511124019753 | L3: 37.7689658337, 128.9079023539 | M3: 7 | N3: 필수
A4: 511126419757 | B4: 마을숲 | C4: 1126400 | D4: 1975700 | E4: 강원특별자치도 | F4: 강릉시 | G4: 송정동 | H4: 강원특별자치도 강릉시 송정동 123-3 | I4: =VLOOKUP(A:A,조사결과표!B:G,7,0) -> #N/A | J4: 강릉시_필수_3 | K4: 511126419757 | L4: 37.7722413235, 128.9352139744 | M4: 3 | N4: 필수
A5: 511122719736 | B5: 도시숲 | C5: 1122700 | D5: 1973600 | E5: 강원특별자치도 | F5: 강릉시 | G5: 임당동 | H5: 강원특별자치도 강릉시 임당동 149 | I5: =VLOOKUP(A:A,조사결과표!B:G,7,0) -> #N/A | J5: 강릉시_필수_4 | K5: 511122719736 | L5: 37.7538232264, 128.8928587923 | M5: 14 | N5: 필수
A6: 511127019754 | B6: 경관숲 | C6: 1127000 | D6: 1975400 | E6: 강원특별자치도 | F6: 강릉시 | G6: 병산동 | H6: 강원특별자치도 강릉시 병산동 228-1 | I6: =VLOOKUP(A:A,조사결과표!B:G,7,0) -> #N/A | J6: 강릉시_필수_5 | K6: 511127019754 | L6: 37.7694550429, 128.9419722169 | M6: 2 | N6: 필수
A7: 511117319895 | B7: 경관숲 | C7: 1117300 | D7: 1989500 | E7: 강원특별자치도 | F7: 강릉시 | G7: 주문진읍 | H7: 강원특별자치도 강릉시 주문진읍 주문리 187-2 | I7: =VLOOKUP(A:A,조사결과표!B:G,7,0) -> #N/A | J7: 강릉시_필수_6 | K7: 511117319895 | L7: 37.8978021505, 128.8341522568 | M7: 11 | N7: 필수
A8: 511116619878 | B8: 경관숲 | C8: 1116600 | D8: 1987800 | E8: 강원특별자치도 | F8: 강릉시 | G8: 주문진읍 | H8: 강원특별자치도 강릉시 주문진읍 교항리 103-10 | I8: =VLOOKUP(A:A,조사결과표!B:G,7,0) -> #N/A | J8: 강릉시_필수_7 | K8: 511116619878 | L8: 37.8825740113, 128.8259177443 | M8: 3 | N8: 필수
A9: 511122619740 | B9: 마을숲 | C9: 1122600 | D9: 1974000 | E9: 강원특별자치도 | F9: 강릉시 | G9: 교동 | H9: 강원특별자치도 강릉시 교동 913-4 | I9: =VLOOKUP(A:A,조사결과표!B:G,7,0) -> #N/A | J9: 강릉시_필수_8 | K9: 511122619740 | L9: 37.7574408789, 128.8917914568 | M9: 16 | N9: 필수
A10: 511120619734 | B10: 마을숲 | C10: 1120600 | D10: 1973400 | E10: 강원특별자치도 | F10: 강릉시 | G10: 홍제동 | H10: 강원특별자치도 강릉시 홍제동 1044 | I10: =VLOOKUP(A:A,조사결과표!B:G,7,0) -> #N/A | J10: 강릉시_필수_9 | K10: 511120619734 | L10: 37.752300378, 128.8689932262 | M10: 55 | N10: 필수
A11: 511120319766 | B11: 경관숲 | C11: 1120300 | D11: 1976600 | E11: 강원특별자치도 | F11: 강릉시 | G11: 죽헌동 | H11: 강원특별자치도 강릉시 죽헌동 924 | I11: =VLOOKUP(A:A,조사결과표!B:G,7,0) -> #N/A | J11: 강릉시_필수_10 | K11: 511120319766 | L11: 37.7811740907, 128.8661190668 | M11: 20 | N11: 필수
A12: 511120519743 | B12: 마을숲 | C12: 1120500 | D12: 1974300 | E12: 강원특별자치도 | F12: 강릉시 | G12: 유천동 | H12: 강원특별자치도 강릉시 유천동 781 | I12: =VLOOKUP(A:A,조사결과표!B:G,7,0) -> #N/A | J12: 강릉시_필수_11 | K12: 511120519743 | L12: 37.7604231854, 128.8680077196 | M12: 23 | N12: 필수
A13: 511126219759 | B13: 마을숲 | C13: 1126200 | D13: 1975900 | E13: 강원특별자치도 | F13: 강릉시 | G13: 송정동 | H13: 강원특별자치도 강릉시 송정동 1065 | I13: =VLOOKUP(A:A,조사결과표!B:G,7,0) -> #N/A | J13: 강릉시_필수_12 | K13: 511126219759 | L13: 37.7740710417, 128.932978506 | M13: 5 | N13: 필수
... A126: 511090820227 | B126: 마을숲 | C126: 1090800 | D126: 2022700 | E126: 강원특별자치도 | F126: 속초시 | G126: 노학동 | H126: 강원특별자치도 속초시 노학동 산165-34 | I126: =VLOOKUP(A:A,조사결과표!B:G,7,0) -> #N/A | J126: 속초시_예비_8 | K126: 511090820227 | L126: 38.2000092399, 128.5370094298 | M126: 55 | N126: 예비
A127: 511047320218 | B127: 가로수 | C127: 1047300 | D127: 2021800 | E127: 강원특별자치도 | F127: 양구군 | G127: 동면 | H127: 강원특별자치도 양구군 동면 임당리 700-2 | I127: =VLOOKUP(A:A,조사결과표!B:G,7,0) -> #N/A | J127: 양구군_필수_1 | K127: 511047320218 | L127: 38.1952353371, 128.040174089 | M127: 278 | N127: 필수 | O127: 5
A128: 511047420220 | B128: 가로수 | C128: 1047400 | D128: 2022000 | E128: 강원특별자치도 | F128: 양구군 | G128: 동면 | H128: 강원특별자치도 양구군 동면 임당리 623-3 | I128: =VLOOKUP(A:A,조사결과표!B:G,7,0) -> #N/A | J128: 양구군_필수_2 | K128: 511047420220 | L128: 38.1970325167, 128.0413294028 | M128: 278 | N128: 필수 | O128: 5
A129: 511043120105 | B129: 경관숲 | C129: 1043100 | D129: 2010500 | E129: 강원특별자치도 | F129: 양구군 | G129: 양구읍 | H129: 강원특별자치도 양구군 양구읍 송청리 87-50 | I129: =VLOOKUP(A:A,조사결과표!B:G,7,0) -> #N/A | J129: 양구군_필수_3 | K129: 511043120105 | L129: 38.0936067083, 127.9915273082 | M129: 188 | N129: 필수 | O129: 5
A130: 511042020109 | B130: 경관숲 | C130: 1042000 | D130: 2010900 | E130: 강원특별자치도 | F130: 양구군 | G130: 양구읍 | H130: 강원특별자치도 양구군 양구읍 정림리 255-1 | I130: =VLOOKUP(A:A,조사결과표!B:G,7,0) -> #N/A | J130: 양구군_필수_4 | K130: 511042020109 | L130: 38.0972634847, 127.9790064667 | M130: 201 | N130: 필수 | O130: 5
A131: 511042320118 | B131: 경관숲 | C131: 1042300 | D131: 2011800 | E131: 강원특별자치도 | F131: 양구군 | G131: 양구읍 | H131: 강원특별자치도 양구군 양구읍 상리 394 | I131: =VLOOKUP(A:A,조사결과표!B:G,7,0) -> #N/A | J131: 양구군_필수_5 | K131: 511042320118 | L131: 38.1053606697, 127.9824811649 | M131: 181 | N131: 필수 | O131: 5
A132: 511047520225 | B132: 학교숲 | C132: 1047500 | D132: 2022500 | E132: 강원특별자치도 | F132: 양구군 | G132: 동면 | H132: 강원특별자치도 양구군 동면 임당리 564 | I132: =VLOOKUP(A:A,조사결과표!B:G,7,0) -> #N/A | J132: 양구군_필수_6 | K132: 511047520225 | L132: 38.2015333401, 128.0425048354 | M132: 295 | N132: 필수 | O132: 5
A133: 511043420142 | B133: 경관숲 | C133: 1043400 | D133: 2014200 | E133: 강원특별자치도 | F133: 양구군 | G133: 양구읍 | H133: 강원특별자치도 양구군 양구읍 하리 639-4 | I133: =VLOOKUP(A:A,조사결과표!B:G,7,0) -> #N/A | J133: 양구군_필수_7 | K133: 511043420142 | L133: 38.1269382035, 127.995173562 | M133: 184 | N133: 필수 | O133: 5
A134: 511042720111 | B134: 마을숲 | C134: 1042700 | D134: 2011100 | E134: 강원특별자치도 | F134: 양구군 | G134: 양구읍 | H134: 강원특별자치도 양구군 양구읍 상리 609 | I134: =VLOOKUP(A:A,조사결과표!B:G,7,0) -> #N/A | J134: 양구군_필수_8 | K134: 511042720111 | L134: 38.0990331555, 127.9870016065 | M134: 188 | N134: 필수 | O134: 5
A135: 511043120113 | B135: 학교숲 | C135: 1043100 | D135: 2011300 | E135: 강원특별자치도 | F135: 양구군 | G135: 양구읍 | H135: 강원특별자치도 양구군 양구읍 상리 186-3 | I135: =VLOOKUP(A:A,조사결과표!B:G,7,0) -> #N/A | J135: 양구군_필수_9 | K135: 511043120113 | L135: 38.1008166428, 127.9915756038 | M135: 188 | N135: 필수 | O135: 5
A136: 511042620125 | B136: 경관숲 | C136: 1042600 | D136: 2012500 | E136: 강원특별자치도 | F136: 양구군 | G136: 양구읍 | H136: 강원특별자치도 양구군 양구읍 하리 118-7 | I136: =VLOOKUP(A:A,조사결과표!B:G,7,0) -> #N/A | J136: 양구군_필수_10 | K136: 511042620125 | L136: 38.1116552552, 127.9859446959 | M136: 182 | N136: 필수 | O136: 5
A137: 511042720112 | B137: 마을숲 | C137: 1042700 | D137: 2011200 | E137: 강원특별자치도 | F137: 양구군 | G137: 양구읍 | H137: 강원특별자치도 양구군 양구읍 상리 584 | I137: =VLOOKUP(A:A,조사결과표!B:G,7,0) -> #N/A | J137: 양구군_필수_11 | K137: 511042720112 | L137: 38.0999343976, 127.9870075881 | M137: 187 | N137: 필수 | O137: 5
A138: 511053720284 | B138: 경관숲 | C138: 1053700 | D138: 2028400 | E138: 강원특별자치도 | F138: 양구군 | G138: 해안면 | H138: 강원특별자치도 양구군 해안면 만대리 2641 | I138: =VLOOKUP(A:A,조사결과표!B:G,7,0) -> #N/A | J138: 양구군_필수_12 | K138: 511053720284 | L138: 38.2543557824, 128.1137591173 | M138: 577 | N138: 필수 | O138: 5
... A147: 511042020123 | B147: 경관숲 | C147: 1042000 | D147: 2012300 | E147: 강원특별자치도 | F147: 양구군 | G147: 양구읍 | H147: 강원특별자치도 양구군 양구읍 하리 229-1 | I147: =VLOOKUP(A:A,조사결과표!B:G,7,0) -> #N/A | J147: 양구군_예비_7 | K147: 511042020123 | L147: 38.1098808799, 127.979088853 | M147: 195 | N147: 예비 | O147: 5
A148: 511101420111 | B148: 가로수 | C148: 1101400 | D148: 2011100 | E148: 강원특별자치도 | F148: 양양군 | G148: 손양면 | H148: 강원특별자치도 양양군 손양면 가평리 산2-2 | I148: =VLOOKUP(A:A,조사결과표!B:G,7,0) -> #N/A | J148: 양양군_필수_1 | K148: 511101420111 | L148: 38.094351992, 128.6563968985 | M148: 3 | N148: 필수
A149: 511099320134 | B149: 가로수 | C149: 1099300 | D149: 2013400 | E149: 강원특별자치도 | F149: 양양군 | G149: 강현면 | H149: 강원특별자치도 양양군 강현면 주청리 2-75 | I149: =VLOOKUP(A:A,조사결과표!B:G,7,0) -> #N/A | J149: 양양군_필수_2 | K149: 511099320134 | L149: 38.1153104529, 128.6327722137 | M149: 3 | N149: 필수
A150: 511099320099 | B150: 경관숲 | C150: 1099300 | D150: 2009900 | E150: 강원특별자치도 | F150: 양양군 | G150: 양양읍 | H150: 강원특별자치도 양양군 양양읍 송암리 107-2 | I150: =VLOOKUP(A:A,조사결과표!B:G,7,0) -> #N/A | J150: 양양군_필수_3 | K150: 511099320099 | L150: 38.083772016, 128.6322853814 | M150: 2 | N150: 필수
A151: 511105120024 | B151: 학교숲 | C151: 1105100 | D151: 2002400 | E151: 강원특별자치도 | F151: 양양군 | G151: 현북면 | H151: 강원특별자치도 양양군 현북면 상광정리 577 | I151: =VLOOKUP(A:A,조사결과표!B:G,7,0) -> #N/A | J151: 양양군_필수_4 | K151: 511105120024 | L151: 38.015534892, 128.6973065184 | M151: 16 | N151: 필수
A152: 511097420088 | B152: 마을숲 | C152: 1097400 | D152: 2008800 | E152: 강원특별자치도 | F152: 양양군 | G152: 양양읍 | H152: 강원특별자치도 양양군 양양읍 임천리 37-3 | I152: =VLOOKUP(A:A,조사결과표!B:G,7,0) -> #N/A | J152: 양양군_필수_5 | K152: 511097420088 | L152: 38.0740665539, 128.6104741681 | M152: 11 | N152: 필수
A153: 511096620178 | B153: 경관숲 | C153: 1096600 | D153: 2017800 | E153: 강원특별자치도 | F153: 양양군 | G153: 강현면 | H153: 강원특별자치도 양양군 강현면 물치리 184 | I153: =VLOOKUP(A:A,조사결과표!B:G,7,0) -> #N/A | J153: 양양군_필수_6 | K153: 511096620178 | L153: 38.1552518462, 128.6025735271 | M153: 47 | N153: 필수
A154: 511110319987 | B154: 마을숲 | C154: 1110300 | D154: 1998700 | E154: 강원특별자치도 | F154: 양양군 | G154: 현남면 | H154: 강원특별자치도 양양군 현남면 동산리 산15-1 | I154: =VLOOKUP(A:A,조사결과표!B:G,7,0) -> #N/A | J154: 양양군_필수_7 | K154: 511110319987 | L154: 37.9815771472, 128.7559636742 | M154: 6 | N154: 필수
A155: 511099220139 | B155: 경관숲 | C155: 1099200 | D155: 2013900 | E155: 강원특별자치도 | F155: 양양군 | G155: 강현면 | H155: 강원특별자치도 양양군 강현면 전진리 7-63 | I155: =VLOOKUP(A:A,조사결과표!B:G,7,0) -> #N/A | J155: 양양군_필수_8 | K155: 511099220139 | L155: 38.1198269236, 128.631701201 | M155: 4 | N155: 필수
A156: 511097420087 | B156: 경관숲 | C156: 1097400 | D156: 2008700 | E156: 강원특별자치도 | F156: 양양군 | G156: 양양읍 | H156: 강원특별자치도 양양군 양양읍 서문리 332-2 | I156: =VLOOKUP(A:A,조사결과표!B:G,7,0) -> #N/A | J156: 양양군_필수_9 | K156: 511097420087 | L156: 38.073165445, 128.6104605422 | M156: 10 | N156: 필수
A157: 511098020091 | B157: 마을숲 | C157: 1098000 | D157: 2009100 | E157: 강원특별자치도 | F157: 양양군 | G157: 양양읍 | H157: 강원특별자치도 양양군 양양읍 군행리 17-3 | I157: =VLOOKUP(A:A,조사결과표!B:G,7,0) -> #N/A | J157: 양양군_필수_10 | K157: 511098020091 | L157: 38.0767050456, 128.6173548089 | M157: 26 | N157: 필수
A158: 511096220174 | B158: 마을숲 | C158: 1096200 | D158: 2017400 | E158: 강원특별자치도 | F158: 양양군 | G158: 강현면 | H158: 강원특별자치도 양양군 강현면 강선리 33-4 | I158: =VLOOKUP(A:A,조사결과표!B:G,7,0) -> #N/A | J158: 양양군_필수_11 | K158: 511096220174 | L158: 38.1516902118, 128.597954735 | M158: 6 | N158: 필수
A159: 511099420100 | B159: 경관숲 | C159: 1099400 | D159: 2010000 | E159: 강원특별자치도 | F159: 양양군 | G159: 양양읍 | H159: 강원특별자치도 양양군 양양읍 송암리 97-3 | I159: =VLOOKUP(A:A,조사결과표!B:G,7,0) -> #N/A | J159: 양양군_필수_12 | K159: 511099420100 | L159: 38.0846621253, 128.6334393559 | M159: 2 | N159: 필수
... A171: 511096720175 | B171: 마을숲 | C171: 1096700 | D171: 2017500 | E171: 강원특별자치도 | F171: 양양군 | G171: 강현면 | H171: 강원특별자치도 양양군 강현면 물치리 223-2 | I171: =VLOOKUP(A:A,조사결과표!B:G,7,0) -> #N/A | J171: 양양군_예비_8 | K171: 511096720175 | L171: 38.1525378304, 128.6036739666 | M171: 5 | N171: 예비
...

Sheet 조사결과표
A1: 차수 | B1: 표본점번호 | C1: 광역시도 | D1: 시군구 | E1: 유형 | F1: 조사일자 | G1: 조사가능불가 | H1: 제외사유 | I1: 팀장 | J1: 팀원 | K1: 팀원 | L1: 엑셀 | M1: 사진 | N1: 표본점사진 | O1: 구조물사진 | P1: 라이다촬영 | Q1: 비고
A2: 1 | B2: 410977119997 | C2: =VLOOKUP($B:$B,표본점목록!$A:$E,5,0) -> 경기도 | D2: =VLOOKUP($B:$B,표본점목록!$A:$J,6,0) -> 포천시 | E2: =VLOOKUP(B:B,표본점목록!$A:$B,2,0) -> 경관숲 | F2: 20260707 | G2: 조사가능 | I2: 한성안 | J2: 한승훈 | L2: O | M2: O | N2: 5 | O2: 3
A3: 1 | B3: 410977120007 | C3: =VLOOKUP($B:$B,표본점목록!$A:$E,5,0) -> 경기도 | D3: =VLOOKUP($B:$B,표본점목록!$A:$J,6,0) -> 포천시 | E3: =VLOOKUP(B:B,표본점목록!$A:$B,2,0) -> 경관숲 | F3: 20260707 | G3: 조사가능 | I3: 한성안 | J3: 한승훈 | L3: O | M3: O | N3: 5 | O3: 3
A4: 1 | B4: 410977320001 | C4: =VLOOKUP($B:$B,표본점목록!$A:$E,5,0) -> 경기도 | D4: =VLOOKUP($B:$B,표본점목록!$A:$J,6,0) -> 포천시 | E4: =VLOOKUP(B:B,표본점목록!$A:$B,2,0) -> 마을숲 | F4: 20260707 | G4: 조사가능 | I4: 한성안 | J4: 한승훈 | L4: O | M4: O | N4: 5 | O4: 3
A5: 1 | B5: 410977820012 | C5: =VLOOKUP($B:$B,표본점목록!$A:$E,5,0) -> 경기도 | D5: =VLOOKUP($B:$B,표본점목록!$A:$J,6,0) -> 포천시 | E5: =VLOOKUP(B:B,표본점목록!$A:$B,2,0) -> 경관숲 | F5: 20260707 | G5: 조사가능 | I5: 한성안 | J5: 한승훈 | L5: O | M5: O | N5: 5 | O5: 3
A6: 1 | B6: 410977820014 | C6: =VLOOKUP($B:$B,표본점목록!$A:$E,5,0) -> 경기도 | D6: =VLOOKUP($B:$B,표본점목록!$A:$J,6,0) -> 포천시 | E6: =VLOOKUP(B:B,표본점목록!$A:$B,2,0) -> 경관숲 | F6: 20260707 | G6: 조사가능 | I6: 한성안 | J6: 한승훈 | L6: O | M6: O | N6: 5 | O6: 3
A7: 1 | B7: 410978220174 | C7: =VLOOKUP($B:$B,표본점목록!$A:$E,5,0) -> 경기도 | D7: =VLOOKUP($B:$B,표본점목록!$A:$J,6,0) -> 포천시 | E7: =VLOOKUP(B:B,표본점목록!$A:$B,2,0) -> 학교숲 | F7: 20260707 | G7: 조사가능 | I7: 한성안 | J7: 한승훈 | L7: O | M7: O | N7: 5 | O7: 3
A8: 1 | B8: 410978320175 | C8: =VLOOKUP($B:$B,표본점목록!$A:$E,5,0) -> 경기도 | D8: =VLOOKUP($B:$B,표본점목록!$A:$J,6,0) -> 포천시 | E8: =VLOOKUP(B:B,표본점목록!$A:$B,2,0) -> 마을숲 | F8: 20260707 | G8: 조사가능 | I8: 한성안 | J8: 한승훈 | L8: O | M8: O | N8: 5 | O8: 3
A9: 1 | B9: 410980120098 | C9: =VLOOKUP($B:$B,표본점목록!$A:$E,5,0) -> 경기도 | D9: =VLOOKUP($B:$B,표본점목록!$A:$J,6,0) -> 포천시 | E9: =VLOOKUP(B:B,표본점목록!$A:$B,2,0) -> 마을숲 | F9: 20260707 | G9: 조사가능 | I9: 한성안 | J9: 한승훈 | L9: O | M9: O | N9: 5 | O9: 3
A10: 1 | B10: 410980320101 | C10: =VLOOKUP($B:$B,표본점목록!$A:$E,5,0) -> 경기도 | D10: =VLOOKUP($B:$B,표본점목록!$A:$J,6,0) -> 포천시 | E10: =VLOOKUP(B:B,표본점목록!$A:$B,2,0) -> 학교숲 | F10: 20260707 | G10: 조사가능 | I10: 한성안 | J10: 한승훈 | L10: O | M10: O | N10: 5 | O10: 3
A11: 1 | B11: 410988120021 | C11: =VLOOKUP($B:$B,표본점목록!$A:$E,5,0) -> 경기도 | D11: =VLOOKUP($B:$B,표본점목록!$A:$J,6,0) -> 포천시 | E11: =VLOOKUP(B:B,표본점목록!$A:$B,2,0) -> 경관숲 | F11: 20260707 | G11: 조사가능 | I11: 한성안 | J11: 한승훈 | L11: O | M11: O | N11: 5 | O11: 3
A12: 1 | B12: 410971919877 | C12: =VLOOKUP($B:$B,표본점목록!$A:$E,5,0) -> 경기도 | D12: =VLOOKUP($B:$B,표본점목록!$A:$J,6,0) -> 포천시 | E12: =VLOOKUP(B:B,표본점목록!$A:$B,2,0) -> 경관숲 | F12: 20260708 | G12: 조사가능 | I12: 한성안 | J12: 한승훈 | L12: O | M12: O | N12: 5 | O12: -
A13: 1 | B13: 410973319887 | C13: =VLOOKUP($B:$B,표본점목록!$A:$E,5,0) -> 경기도 | D13: =VLOOKUP($B:$B,표본점목록!$A:$J,6,0) -> 포천시 | E13: =VLOOKUP(B:B,표본점목록!$A:$B,2,0) -> 마을숲 | F13: 20260708 | G13: 조사가능 | I13: 한성안 | J13: 한승훈 | L13: O | M13: O | N13: 5 | O13: 3
A14: 1 | B14: 410973519888 | C14: =VLOOKUP($B:$B,표본점목록!$A:$E,5,0) -> 경기도 | D14: =VLOOKUP($B:$B,표본점목록!$A:$J,6,0) -> 포천시 | E14: =VLOOKUP(B:B,표본점목록!$A:$B,2,0) -> 가로수 | F14: 20260708 | G14: 조사가능 | I14: 한성안 | J14: 한승훈 | L14: O | M14: O | N14: 5 | O14: -
A15: 1 | B15: 410973519894 | C15: =VLOOKUP($B:$B,표본점목록!$A:$E,5,0) -> 경기도 | D15: =VLOOKUP($B:$B,표본점목록!$A:$J,6,0) -> 포천시 | E15: =VLOOKUP(B:B,표본점목록!$A:$B,2,0) -> 경관숲 | F15: 20260708 | G15: 조사가능 | I15: 한성안 | J15: 한승훈 | L15: O | M15: O | N15: 5 | O15: 3
A16: 1 | B16: 410973919870 | C16: =VLOOKUP($B:$B,표본점목록!$A:$E,5,0) -> 경기도 | D16: =VLOOKUP($B:$B,표본점목록!$A:$J,6,0) -> 포천시 | E16: =VLOOKUP(B:B,표본점목록!$A:$B,2,0) -> 도시숲 | F16: 20260708 | G16: 조사가능 | I16: 한성안 | J16: 한승훈 | L16: O | M16: O | N16: 5 | O16: 3
A17: 1 | B17: 410974119871 | C17: =VLOOKUP($B:$B,표본점목록!$A:$E,5,0) -> 경기도 | D17: =VLOOKUP($B:$B,표본점목록!$A:$J,6,0) -> 포천시 | E17: =VLOOKUP(B:B,표본점목록!$A:$B,2,0) -> 도시숲 | F17: 20260708 | G17: 조사가능 | I17: 한성안 | J17: 한승훈 | L17: O | M17: O | N17: 5 | O17: 3
A18: 1 | B18: 410974419890 | C18: =VLOOKUP($B:$B,표본점목록!$A:$E,5,0) -> 경기도 | D18: =VLOOKUP($B:$B,표본점목록!$A:$J,6,0) -> 포천시 | E18: =VLOOKUP(B:B,표본점목록!$A:$B,2,0) -> 마을숲 | F18: 20260708 | G18: 조사가능 | I18: 한성안 | J18: 한승훈 | L18: O | M18: O | N18: 5 | O18: 3
A19: 1 | B19: 410974819877 | C19: =VLOOKUP($B:$B,표본점목록!$A:$E,5,0) -> 경기도 | D19: =VLOOKUP($B:$B,표본점목록!$A:$J,6,0) -> 포천시 | E19: =VLOOKUP(B:B,표본점목록!$A:$B,2,0) -> 경관숲 | F19: 20260708 | G19: 조사가능 | I19: 한성안 | J19: 한승훈 | L19: O | M19: O | N19: 5 | O19: 3
A20: 1 | B20: 410974819901 | C20: =VLOOKUP($B:$B,표본점목록!$A:$E,5,0) -> 경기도 | D20: =VLOOKUP($B:$B,표본점목록!$A:$J,6,0) -> 포천시 | E20: =VLOOKUP(B:B,표본점목록!$A:$B,2,0) -> 경관숲 | F20: 20260708 | G20: 조사가능 | I20: 한성안 | J20: 한승훈 | L20: O | M20: O | N20: 5 | O20: 3
A21: 1 | B21: 410974919876 | C21: =VLOOKUP($B:$B,표본점목록!$A:$E,5,0) -> 경기도 | D21: =VLOOKUP($B:$B,표본점목록!$A:$J,6,0) -> 포천시 | E21: =VLOOKUP(B:B,표본점목록!$A:$B,2,0) -> 가로수 | F21: 20260708 | G21: 조사가능 | I21: 한성안 | J21: 한승훈 | L21: O | M21: O | N21: 5 | O21: -
A22: 1 | B22: 410975119877 | C22: =VLOOKUP($B:$B,표본점목록!$A:$E,5,0) -> 경기도 | D22: =VLOOKUP($B:$B,표본점목록!$A:$J,6,0) -> 포천시 | E22: =VLOOKUP(B:B,표본점목록!$A:$B,2,0) -> 마을숲 | F22: 20260708 | G22: 조사가능 | I22: 한성안 | J22: 한승훈 | L22: O | M22: O | N22: 5 | O22: 3
A23: 1 | B23: 410971719880 | C23: =VLOOKUP($B:$B,표본점목록!$A:$E,5,0) -> 경기도 | D23: =VLOOKUP($B:$B,표본점목록!$A:$J,6,0) -> 포천시 | E23: =VLOOKUP(B:B,표본점목록!$A:$B,2,0) -> 경관숲 | F23: 20260708 | G23: 조사불가 | H23: 출입금지 | I23: 한성안 | J23: 한승훈 | L23: - | M23: - | N23: - | O23: -
A24: 1 | B24: 410973119897 | C24: =VLOOKUP($B:$B,표본점목록!$A:$E,5,0) -> 경기도 | D24: =VLOOKUP($B:$B,표본점목록!$A:$J,6,0) -> 포천시 | E24: =VLOOKUP(B:B,표본점목록!$A:$B,2,0) -> 경관숲 | F24: 20260708 | G24: 조사불가 | H24: 조경수농장 | I24: 한성안 | J24: 한승훈 | L24: - | M24: - | N24: - | O24: -
A25: 1 | B25: 410974719896 | C25: =VLOOKUP($B:$B,표본점목록!$A:$E,5,0) -> 경기도 | D25: =VLOOKUP($B:$B,표본점목록!$A:$J,6,0) -> 포천시 | E25: =VLOOKUP(B:B,표본점목록!$A:$B,2,0) -> 경관숲 | F25: 20260708 | G25: 조사불가 | H25: 조경수농장 | I25: 한성안 | J25: 한승훈 | L25: - | M25: - | N25: - | O25: -
A26: 1 | B26: 410968719807 | C26: =VLOOKUP($B:$B,표본점목록!$A:$E,5,0) -> 경기도 | D26: =VLOOKUP($B:$B,표본점목록!$A:$J,6,0) -> 포천시 | E26: =VLOOKUP(B:B,표본점목록!$A:$B,2,0) -> 마을숲 | F26: 20260709 | G26: 조사가능 | I26: 한성안 | J26: 한승훈 | L26: O | M26: O | N26: 5 | O26: 3
A27: 1 | B27: 410968319809 | C27: =VLOOKUP($B:$B,표본점목록!$A:$E,5,0) -> 경기도 | D27: =VLOOKUP($B:$B,표본점목록!$A:$J,6,0) -> 포천시 | E27: =VLOOKUP(B:B,표본점목록!$A:$B,2,0) -> 마을숲 | F27: 20260709 | G27: 조사가능 | I27: 한성안 | J27: 한승훈 | L27: O | M27: O | N27: 5 | O27: 3
A28: 1 | B28: 410968419811 | C28: =VLOOKUP($B:$B,표본점목록!$A:$E,5,0) -> 경기도 | D28: =VLOOKUP($B:$B,표본점목록!$A:$J,6,0) -> 포천시 | E28: =VLOOKUP(B:B,표본점목록!$A:$B,2,0) -> 마을숲 | F28: 20260709 | G28: 조사가능 | I28: 한성안 | J28: 한승훈 | L28: O | M28: O | N28: 5 | O28: 3
A29: 1 | B29: 410968819817 | C29: =VLOOKUP($B:$B,표본점목록!$A:$E,5,0) -> 경기도 | D29: =VLOOKUP($B:$B,표본점목록!$A:$J,6,0) -> 포천시 | E29: =VLOOKUP(B:B,표본점목록!$A:$B,2,0) -> 학교숲 | F29: 20260709 | G29: 조사가능 | I29: 한성안 | J29: 한승훈 | L29: O | M29: O | N29: 5 | O29: 3
A30: 1 | B30: 410969019816 | C30: =VLOOKUP($B:$B,표본점목록!$A:$E,5,0) -> 경기도 | D30: =VLOOKUP($B:$B,표본점목록!$A:$J,6,0) -> 포천시 | E30: =VLOOKUP(B:B,표본점목록!$A:$B,2,0) -> 마을숲 | F30: 20260709 | G30: 조사가능 | I30: 한성안 | J30: 한승훈 | L30: O | M30: O | N30: 5 | O30: 3
A31: 1 | B31: 410969219818 | C31: =VLOOKUP($B:$B,표본점목록!$A:$E,5,0) -> 경기도 | D31: =VLOOKUP($B:$B,표본점목록!$A:$J,6,0) -> 포천시 | E31: =VLOOKUP(B:B,표본점목록!$A:$B,2,0) -> 경관숲 | F31: 20260709 | G31: 조사가능 | I31: 한성안 | J31: 한승훈 | L31: O | M31: O | N31: 5 | O31: 3
A32: 1 | B32: 410968919812 | C32: =VLOOKUP($B:$B,표본점목록!$A:$E,5,0) -> 경기도 | D32: =VLOOKUP($B:$B,표본점목록!$A:$J,6,0) -> 포천시 | E32: =VLOOKUP(B:B,표본점목록!$A:$B,2,0) -> 마을숲 | F32: 20260709 | G32: 조사가능 | I32: 한성안 | J32: 한승훈 | L32: O | M32: O | N32: 5 | O32: 3
A33: 1 | B33: 410976619951 | C33: =VLOOKUP($B:$B,표본점목록!$A:$E,5,0) -> 경기도 | D33: =VLOOKUP($B:$B,표본점목록!$A:$J,6,0) -> 포천시 | E33: =VLOOKUP(B:B,표본점목록!$A:$B,2,0) -> 도시숲 | F33: 20260709 | G33: 조사불가 | H33: 무립목지 | I33: 한성안 | J33: 한승훈 | L33: - | M33: - | N33: - | O33: -
A34: 2 | B34: 410969919840 | C34: =VLOOKUP($B:$B,표본점목록!$A:$E,5,0) -> 경기도 | D34: =VLOOKUP($B:$B,표본점목록!$A:$J,6,0) -> 포천시 | E34: =VLOOKUP(B:B,표본점목록!$A:$B,2,0) -> 마을숲 | F34: 20260713 | G34: 조사가능 | I34: 한성안 | J34: 한승훈 | L34: O | M34: O | N34: 5 | O34: 3
A35: 2 | B35: 410970019841 | C35: =VLOOKUP($B:$B,표본점목록!$A:$E,5,0) -> 경기도 | D35: =VLOOKUP($B:$B,표본점목록!$A:$J,6,0) -> 포천시 | E35: =VLOOKUP(B:B,표본점목록!$A:$B,2,0) -> 마을숲 | F35: 20260713 | G35: 조사가능 | I35: 한성안 | J35: 한승훈 | L35: O | M35: O | N35: 5 | O35: 3
A36: 2 | B36: 410973619875 | C36: =VLOOKUP($B:$B,표본점목록!$A:$E,5,0) -> 경기도 | D36: =VLOOKUP($B:$B,표본점목록!$A:$J,6,0) -> 포천시 | E36: =VLOOKUP(B:B,표본점목록!$A:$B,2,0) -> 경관숲 | F36: 20260713 | G36: 조사가능 | I36: 한성안 | J36: 한승훈 | L36: O | M36: O | N36: 5 | O36: 3
A37: 2 | B37: 410975719761 | C37: =VLOOKUP($B:$B,표본점목록!$A:$E,5,0) -> 경기도 | D37: =VLOOKUP($B:$B,표본점목록!$A:$J,6,0) -> 포천시 | E37: =VLOOKUP(B:B,표본점목록!$A:$B,2,0) -> 경관숲 | F37: 20260713 | G37: 조사가능 | I37: 한성안 | J37: 한승훈 | L37: O | M37: O | N37: 5 | O37: 1
A38: 2 | B38: 410975819751 | C38: =VLOOKUP($B:$B,표본점목록!$A:$E,5,0) -> 경기도 | D38: =VLOOKUP($B:$B,표본점목록!$A:$J,6,0) -> 포천시 | E38: =VLOOKUP(B:B,표본점목록!$A:$B,2,0) -> 경관숲 | F38: 20260713 | G38: 조사가능 | I38: 한성안 | J38: 한승훈 | L38: O | M38: O | N38: 5 | O38: 2
A39: 2 | B39: 410976019749 | C39: =VLOOKUP($B:$B,표본점목록!$A:$E,5,0) -> 경기도 | D39: =VLOOKUP($B:$B,표본점목록!$A:$J,6,0) -> 포천시 | E39: =VLOOKUP(B:B,표본점목록!$A:$B,2,0) -> 경관숲 | F39: 20260713 | G39: 조사가능 | I39: 한성안 | J39: 한승훈 | L39: O | M39: O | N39: 5 | O39: 3
A40: 2 | B40: 410977619773 | C40: =VLOOKUP($B:$B,표본점목록!$A:$E,5,0) -> 경기도 | D40: =VLOOKUP($B:$B,표본점목록!$A:$J,6,0) -> 포천시 | E40: =VLOOKUP(B:B,표본점목록!$A:$B,2,0) -> 경관숲 | F40: 20260713 | G40: 조사가능 | I40: 한성안 | J40: 한승훈 | L40: O | M40: O | N40: 5 | O40: 2
...

Sheet 실적
A1: 조사가능불가 | B1: 조사가능 | I1: 조사가능불가 | J1: 조사불가 | Q1: 조사가능불가 | R1: #N/A
A3: 개수 : 표본점번호 | B3: 열 레이블 | I3: 개수 : 표본점번호 | J3: 열 레이블 | Q3: 개수 : 표본점번호 | R3: 열 레이블
A4: 행 레이블 | B4: 도시숲 | C4: 경관숲 | D4: 마을숲 | E4: 학교숲 | F4: 가로수 | G4: 총합계 | I4: 행 레이블 | J4: 도시숲 | K4: 경관숲 | L4: 마을숲 | M4: 학교숲 | N4: 가로수 | O4: 총합계 | Q4: 행 레이블 | R4: 도시숲 | S4: 경관숲 | T4: 마을숲 | U4: 학교숲 | V4: 가로수 | W4: 총합계
A5: 대구광역시 | B5: 16 | C5: 15 | D5: 24 | E5: 1 | F5: 6 | G5: 62 | I5: 대구광역시 | J5: 3 | K5: 2 | L5: 1 | O5: 6 | Q5: 대구광역시 | R5: 16 | S5: 28 | T5: 40 | U5: 7 | V5: 21 | W5: 112
A6: 울산광역시 | B6: 7 | C6: 16 | D6: 31 | E6: 4 | F6: 10 | G6: 68 | I6: 울산광역시 | J6: 2 | L6: 4 | O6: 6 | Q6: 울산광역시 | R6: 8 | S6: 8 | T6: 16 | U6: 1 | V6: 5 | W6: 38
A7: 경상남도 | B7: 8 | C7: 28 | D7: 12 | E7: 6 | F7: 8 | G7: 62 | I7: 경상남도 | J7: 1 | K7: 10 | L7: 3 | N7: 2 | O7: 16 | Q7: 경상북도 | R7: 83 | S7: 227 | T7: 120 | U7: 29 | V7: 63 | W7: 522
A8: 경기도 | B8: 4 | C8: 45 | D8: 22 | E8: 3 | F8: 11 | G8: 85 | I8: 경기도 | J8: 1 | K8: 13 | L8: 3 | N8: 4 | O8: 21 | Q8: 경상남도 | R8: 41 | S8: 132 | T8: 73 | U8: 16 | V8: 44 | W8: 306
A9: 광주광역시 | C9: 3 | D9: 14 | F9: 4 | G9: 21 | I9: 대전광역시 | K9: 1 | N9: 1 | O9: 2 | Q9: 강원특별자치도 | R9: 22 | S9: 235 | T9: 172 | U9: 48 | V9: 54 | W9: 531
A10: 대전광역시 | B10: 1 | C10: 3 | F10: 1 | G10: 5 | I10: 부산광역시 | K10: 2 | L10: 1 | M10: 1 | N10: 2 | O10: 6 | Q10: 경기도 | R10: 44 | S10: 209 | T10: 112 | U10: 12 | V10: 78 | W10: 455
A11: 부산광역시 | B11: 6 | C11: 25 | D11: 9 | E11: 4 | F11: 13 | G11: 57 | I11: 서울특별시 | L11: 3 | N11: 3 | O11: 6 | Q11: 광주광역시 | R11: 4 | S11: 42 | T11: 45 | U11: 4 | V11: 11 | W11: 106
A12: 서울특별시 | B12: 1 | C12: 15 | D12: 30 | E12: 2 | F12: 15 | G12: 63 | I12: 전라남도 | J12: 3 | K12: 18 | L12: 2 | N12: 3 | O12: 26 | Q12: 대전광역시 | R12: 11 | S12: 63 | T12: 49 | U12: 5 | V12: 13 | W12: 141
A13: 전라남도 | B13: 7 | C13: 52 | D13: 23 | E13: 4 | F13: 19 | G13: 105 | I13: 충청남도 | J13: 1 | K13: 6 | N13: 1 | O13: 8 | Q13: 부산광역시 | R13: 21 | S13: 46 | T13: 77 | U13: 8 | V13: 33 | W13: 185
A14: 충청남도 | B14: 2 | C14: 21 | D14: 6 | F14: 6 | G14: 35 | I14: 총합계 | J14: 11 | K14: 52 | L14: 17 | M14: 1 | N14: 16 | O14: 97 | Q14: 서울특별시 | R14: 10 | S14: 76 | T14: 125 | U14: 7 | V14: 57 | W14: 275
A15: 총합계 | B15: 52 | C15: 223 | D15: 171 | E15: 24 | F15: 93 | G15: 563 | Q15: 세종특별자치시 | R15: 2 | S15: 15 | T15: 5 | U15: 2 | V15: 3 | W15: 27
Q16: 인천광역시 | R16: 18 | S16: 86 | T16: 32 | U16: 3 | V16: 30 | W16: 169
Q17: 전라남도 | R17: 15 | S17: 149 | T17: 53 | U17: 4 | V17: 44 | W17: 265
Q18: 전북특별자치도 | R18: 17 | S18: 146 | T18: 49 | U18: 13 | V18: 42 | W18: 267
Q19: 제주특별자치도 | R19: 1 | S19: 105 | T19: 21 | U19: 6 | V19: 6 | W19: 139
Q20: 충청남도 | R20: 27 | S20: 171 | T20: 41 | U20: 10 | V20: 38 | W20: 287
Q21: 충청북도 | R21: 2 | S21: 22 | T21: 7 | V21: 8 | W21: 39
Q22: 총합계 | R22: 342 | S22: 1760 | T22: 1037 | U22: 175 | V22: 550 | W22: 3864
A25: 조사가능불가 | B25: 조사가능 | P25: 라이다촬영 | Q25: (다중 항목)
A27: 개수 : 표본점번호 | B27: 열 레이블 | P27: 개수 : 표본점번호 | Q27: 열 레이블
A28: 행 레이블 | B28: 도시숲 | C28: 경관숲 | D28: 마을숲 | E28: 학교숲 | F28: 가로수 | G28: 총합계 | P28: 행 레이블 | Q28: 총합계
A29: 대구광역시 | B29: 16 | C29: 15 | D29: 24 | E29: 1 | F29: 6 | G29: 62 | P29: 총합계
A30: 울산광역시 | B30: 7 | C30: 16 | D30: 31 | E30: 4 | F30: 10 | G30: 68
A31: 경상남도 | B31: 8 | C31: 28 | D31: 12 | E31: 6 | F31: 8 | G31: 62
A32: 경기도 | B32: 4 | C32: 45 | D32: 22 | E32: 3 | F32: 11 | G32: 85
A33: 광주광역시 | C33: 3 | D33: 14 | F33: 4 | G33: 21
A34: 대전광역시 | B34: 1 | C34: 3 | F34: 1 | G34: 5
A35: 부산광역시 | B35: 6 | C35: 25 | D35: 9 | E35: 4 | F35: 13 | G35: 57
A36: 서울특별시 | B36: 1 | C36: 15 | D36: 30 | E36: 2 | F36: 15 | G36: 63
A37: 전라남도 | B37: 7 | C37: 52 | D37: 23 | E37: 4 | F37: 19 | G37: 105
A38: 충청남도 | B38: 2 | C38: 21 | D38: 6 | F38: 6 | G38: 35
A39: 총합계 | B39: 52 | C39: 223 | D39: 171 | E39: 24 | F39: 93 | G39: 563

Sheet 조사불가
A1: 조사가능불가 | B1: 조사불가
B3: 열 레이블
B4: 도시숲 | C4: 경관숲 | D4: 마을숲 | E4: 학교숲 | F4: 가로수 | G4: 총합계
A5: 개수 : 표본점번호 | B5: 13 | C5: 61 | D5: 17 | E5: 1 | F5: 17 | G5: 109
A18: 조사가능불가 | B18: 조사불가
B20: 열 레이블
B21: 개발지역 | C21: 분류오류 | D21: 협조불가 | E21: 출입금지 | F21: 옥상 | G21: 무립목지 | H21: 조경수농장 | I21: 수계 | J21: 경작지 | K21: 총합계
A22: 개수 : 표본점번호 | B22: 6 | C22: 15 | D22: 30 | E22: 37 | F22: 2 | G22: 13 | H22: 2 | I22: 1 | J22: 3 | K22: 109

Sheet 지역확인
A4: 개수 : 표본점번호 | B4: 열 레이블
B5: 조사가능 | N5: 조사가능 요약 | O5: 조사불가 | W5: 조사불가 요약 | X5: 총합계
B6: 필수 | G6: 필수 요약 | H6: 예비 | M6: 예비 요약 | O6: 필수 | T6: 필수 요약 | U6: 예비 | V6: 예비 요약
A7: 행 레이블 | B7: 도시숲 | C7: 경관숲 | D7: 마을숲 | E7: 학교숲 | F7: 가로수 | H7: 도시숲 | I7: 경관숲 | J7: 마을숲 | K7: 학교숲 | L7: 가로수 | O7: 도시숲 | P7: 경관숲 | Q7: 마을숲 | R7: 학교숲 | S7: 가로수 | U7: 가로수 | Y7: 필수제외수=예비조사수 | Z7: 필수제외수=예비조사수(가로수)
A8: 경상남도 | B8: 8 | C8: 19 | D8: 9 | E8: 4 | F8: 6 | G8: 46 | I8: 9 | J8: 3 | K8: 2 | L8: 2 | M8: 16 | N8: 62 | O8: 1 | P8: 10 | Q8: 3 | S8: 2 | T8: 16 | W8: 16 | X8: 78 | Y8: =SUM(H8:K8)=(IF(SUM(O8:R8)<>"",SUM(O8:R8),"")) -> TRUE | Z8: =L8=S8 -> TRUE
A9: 거창군 | B9: 2 | C9: 10 | D9: 7 | E9: 3 | F9: 2 | G9: 24 | I9: 5 | J9: 2 | K9: 1 | M9: 8 | N9: 32 | P9: 6 | Q9: 2 | T9: 8 | W9: 8 | X9: 40 | Y9: =SUM(H9:K9)=(IF(SUM(O9:R9)<>"",SUM(O9:R9),"")) -> TRUE | Z9: =L9=S9 -> TRUE
A10: 산청군 | B10: 1 | C10: 4 | F10: 1 | G10: 6 | K10: 1 | L10: 1 | M10: 2 | N10: 8 | O10: 1 | S10: 1 | T10: 2 | W10: 2 | X10: 10 | Y10: =SUM(H10:K10)=(IF(SUM(O10:R10)<>"",SUM(O10:R10),"")) -> TRUE | Z10: =L10=S10 -> TRUE
A11: 진주시 | B11: 1 | C11: 2 | D11: 1 | G11: 4 | N11: 4 | X11: 4 | Y11: =SUM(H11:K11)=(IF(SUM(O11:R11)<>"",SUM(O11:R11),"")) -> TRUE | Z11: =L11=S11 -> TRUE
A12: 하동군 | B12: 2 | C12: 2 | F12: 1 | G12: 5 | I12: 2 | J12: 1 | L12: 1 | M12: 4 | N12: 9 | P12: 3 | S12: 1 | T12: 4 | W12: 4 | X12: 13 | Y12: =SUM(H12:K12)=(IF(SUM(O12:R12)<>"",SUM(O12:R12),"")) -> TRUE | Z12: =L12=S12 -> TRUE
A13: 함양군 | B13: 2 | C13: 1 | D13: 1 | E13: 1 | F13: 2 | G13: 7 | I13: 2 | M13: 2 | N13: 9 | P13: 1 | Q13: 1 | T13: 2 | W13: 2 | X13: 11 | Y13: =SUM(H13:K13)=(IF(SUM(O13:R13)<>"",SUM(O13:R13),"")) -> TRUE | Z13: =L13=S13 -> TRUE
A14: 대구광역시 | B14: 15 | C14: 13 | D14: 18 | E14: 1 | F14: 4 | G14: 51 | H14: 1 | I14: 2 | J14: 6 | L14: 2 | M14: 11 | N14: 62 | O14: 3 | P14: 2 | Q14: 1 | T14: 6 | W14: 6 | X14: 68 | Y14: =IF(SUM(O14:R14)<>"",SUM(H14:K14)=SUM(O14:R14)) -> FALSE | Z14: =L14=S14 -> FALSE
A15: 달서구 | B15: 3 | D15: 5 | F15: 2 | G15: 10 | H15: 1 | I15: 1 | J15: 2 | L15: 1 | M15: 5 | N15: 15 | X15: 15 | Y15: =IF(SUM(O15:R15)<>"",SUM(H15:K15)=SUM(O15:R15)) -> FALSE | Z15: =L15=S15 -> FALSE
A16: 달성군 | B16: 3 | C16: 9 | G16: 12 | I16: 1 | J16: 3 | M16: 4 | N16: 16 | O16: 2 | P16: 2 | T16: 4 | W16: 4 | X16: 20 | Y16: =SUM(H16:K16)=(IF(SUM(O16:R16)<>"",SUM(O16:R16),"")) -> TRUE | Z16: =L16=S16 -> TRUE
A17: 수성구 | C17: 2 | D17: 4 | G17: 6 | N17: 6 | X17: 6 | Y17: =SUM(H17:K17)=(IF(SUM(O17:R17)<>"",SUM(O17:R17),"")) -> TRUE | Z17: =L17=S17 -> TRUE
A18: 대구남구 | Q18: 1 | T18: 1 | W18: 1 | X18: 1 | Y18: =IF(SUM(O18:R18)<>"",SUM(H18:K18)=SUM(O18:R18)) -> FALSE | Z18: =L18=S18 -> TRUE
A19: 대구동구 | B19: 1 | D19: 1 | G19: 2 | J19: 1 | M19: 1 | N19: 3 | O19: 1 | T19: 1 | W19: 1 | X19: 4 | Y19: =SUM(H19:K19)=(IF(SUM(O19:R19)<>"",SUM(O19:R19),"")) -> TRUE | Z19: =L19=S19 -> TRUE
A20: 대구북구 | B20: 3 | C20: 1 | D20: 6 | F20: 2 | G20: 12 | L20: 1 | M20: 1 | N20: 13 | X20: 13 | Y20: =SUM(H20:K20)=(IF(SUM(O20:R20)<>"",SUM(O20:R20),"")) -> TRUE | Z20: =L20=S20 -> FALSE
A21: 대구서구 | B21: 4 | D21: 1 | E21: 1 | G21: 6 | N21: 6 | X21: 6 | Y21: =SUM(H21:K21)=(IF(SUM(O21:R21)<>"",SUM(O21:R21),"")) -> TRUE | Z21: =L21=S21 -> TRUE
A22: 대구중구 | B22: 1 | C22: 1 | D22: 1 | G22: 3 | N22: 3 | X22: 3 | Y22: =SUM(H22:K22)=(IF(SUM(O22:R22)<>"",SUM(O22:R22),"")) -> TRUE | Z22: =L22=S22 -> TRUE
A23: 울산광역시 | B23: 7 | C23: 11 | D23: 27 | E23: 4 | F23: 10 | G23: 59 | I23: 5 | J23: 4 | M23: 9 | N23: 68 | O23: 2 | Q23: 4 | T23: 6 | W23: 6 | X23: 74 | Y23: =IF(SUM(O23:R23)<>"",SUM(H23:K23)=SUM(O23:R23)) -> FALSE | Z23: =L23=S23 -> TRUE
A24: 남구 | B24: 3 | C24: 2 | D24: 3 | E24: 1 | F24: 2 | G24: 11 | I24: 2 | J24: 1 | M24: 3 | N24: 14 | X24: 14 | Y24: =IF(SUM(O24:R24)<>"",SUM(H24:K24)=SUM(O24:R24)) -> FALSE | Z24: =L24=S24 -> TRUE
A25: 동구 | D25: 9 | E25: 1 | F25: 2 | G25: 12 | J25: 2 | M25: 2 | N25: 14 | Q25: 2 | T25: 2 | W25: 2 | X25: 16 | Y25: =SUM(H25:K25)=(IF(SUM(O25:R25)<>"",SUM(O25:R25),"")) -> TRUE | Z25: =L25=S25 -> TRUE
A26: 북구 | C26: 4 | D26: 5 | F26: 2 | G26: 11 | I26: 2 | M26: 2 | N26: 13 | O26: 2 | T26: 2 | W26: 2 | X26: 15 | Y26: =SUM(H26:K26)=(IF(SUM(O26:R26)<>"",SUM(O26:R26),"")) -> TRUE | Z26: =L26=S26 -> TRUE
A27: 울주군 | B27: 3 | C27: 1 | D27: 4 | E27: 1 | F27: 2 | G27: 11 | I27: 1 | M27: 1 | N27: 12 | Q27: 1 | T27: 1 | W27: 1 | X27: 13 | Y27: =SUM(H27:K27)=(IF(SUM(O27:R27)<>"",SUM(O27:R27),"")) -> TRUE | Z27: =L27=S27 -> TRUE
A28: 중구 | B28: 1 | C28: 4 | D28: 6 | E28: 1 | F28: 2 | G28: 14 | J28: 1 | M28: 1 | N28: 15 | Q28: 1 | T28: 1 | W28: 1 | X28: 16 | Y28: =SUM(H28:K28)=(IF(SUM(O28:R28)<>"",SUM(O28:R28),"")) -> TRUE | Z28: =L28=S28 -> TRUE
A29: 경기도 | B29: 4 | C29: 36 | D29: 16 | E29: 3 | F29: 8 | G29: 67 | I29: 9 | J29: 6 | L29: 3 | M29: 18 | N29: 85 | O29: 1 | P29: 13 | Q29: 3 | S29: 4 | T29: 21 | W29: 21 | X29: 106 | Y29: =IF(SUM(O29:R29)<>"",SUM(H29:K29)=SUM(O29:R29)) -> FALSE | Z29: =L29=S29 -> FALSE
A30: 동두천시 | C30: 2 | D30: 2 | F30: 1 | G30: 5 | I30: 1 | L30: 1 | M30: 2 | N30: 7 | P30: 2 | S30: 1 | T30: 3 | W30: 3 | X30: 10 | Y30: =IF(SUM(O30:R30)<>"",SUM(H30:K30)=SUM(O30:R30)) -> FALSE | Z30: =L30=S30 -> TRUE
A31: 양주시 | C31: 6 | D31: 3 | F31: 1 | G31: 10 | J31: 1 | L31: 1 | M31: 2 | N31: 12 | P31: 2 | S31: 1 | T31: 3 | W31: 3 | X31: 15 | Y31: =IF(SUM(O31:R31)<>"",SUM(H31:K31)=SUM(O31:R31)) -> FALSE | Z31: =L31=S31 -> TRUE
A32: 여주시 | C32: 4 | F32: 2 | G32: 6 | I32: 1 | M32: 1 | N32: 7 | P32: 1 | T32: 1 | W32: 1 | X32: 8 | Y32: =SUM(H32:K32)=(IF(SUM(O32:R32)<>"",SUM(O32:R32),"")) -> TRUE | Z32: =L32=S32 -> TRUE
A33: 연천군 | B33: 2 | C33: 3 | F33: 2 | G33: 7 | I33: 1 | M33: 1 | N33: 8 | P33: 1 | T33: 1 | W33: 1 | X33: 9 | Y33: =SUM(H33:K33)=(IF(SUM(O33:R33)<>"",SUM(O33:R33),"")) -> TRUE | Z33: =L33=S33 -> TRUE
A34: 의정부시 | C34: 7 | G34: 7 | J34: 1 | L34: 1 | M34: 2 | N34: 9 | P34: 1 | S34: 2 | T34: 3 | W34: 3 | X34: 12 | Y34: =SUM(H34:K34)=(IF(SUM(O34:R34)<>"",SUM(O34:R34),"")) -> TRUE | Z34: =L34=S34 -> FALSE
A35: 포천시 | B35: 2 | C35: 14 | D35: 11 | E35: 3 | F35: 2 | G35: 32 | I35: 6 | J35: 4 | M35: 10 | N35: 42 | O35: 1 | P35: 6 | Q35: 3 | T35: 10 | W35: 10 | X35: 52 | Y35: =SUM(H35:K35)=(IF(SUM(O35:R35)<>"",SUM(O35:R35),"")) -> TRUE | Z35: =L35=S35 -> TRUE
A36: 광주광역시 | C36: 3 | D36: 13 | F36: 3 | G36: 19 | J36: 1 | L36: 1 | M36: 2 | N36: 21 | X36: 21 | Y36: =IF(SUM(O36:R36)<>"",SUM(H36:K36)=SUM(O36:R36)) -> FALSE | Z36: =L36=S36 -> FALSE
A37: 광산구 | C37: 2 | D37: 2 | F37: 2 | G37: 6 | N37: 6 | X37: 6 | Y37: =SUM(H37:K37)=(IF(SUM(O37:R37)<>"",SUM(O37:R37),"")) -> TRUE | Z37: =L37=S37 -> TRUE
A38: 광주동구 | L38: 1 | M38: 1 | N38: 1 | X38: 1 | Y38: =SUM(H38:K38)=(IF(SUM(O38:R38)<>"",SUM(O38:R38),"")) -> TRUE | Z38: =L38=S38 -> FALSE
A39: 광주북구 | D39: 10 | F39: 1 | G39: 11 | J39: 1 | M39: 1 | N39: 12 | X39: 12 | Y39: =IF(SUM(O39:R39)<>"",SUM(H39:K39)=SUM(O39:R39)) -> FALSE | Z39: =L39=S39 -> TRUE
A40: 광주서구 | C40: 1 | D40: 1 | G40: 2 | N40: 2 | X40: 2 | Y40: =SUM(H40:K40)=(IF(SUM(O40:R40)<>"",SUM(O40:R40),"")) -> TRUE | Z40: =L40=S40 -> TRUE
A41: 대전광역시 | B41: 1 | C41: 3 | G41: 4 | L41: 1 | M41: 1 | N41: 5 | P41: 1 | S41: 1 | T41: 2 | W41: 2 | X41: 7 | Y41: =IF(SUM(O41:R41)<>"",SUM(H41:K41)=SUM(O41:R41)) -> FALSE | Z41: =L41=S41 -> TRUE
A42: 대덕구 | B42: 1 | C42: 3 | G42: 4 | L42: 1 | M42: 1 | N42: 5 | P42: 1 | S42: 1 | T42: 2 | W42: 2 | X42: 7 | Y42: =IF(SUM(O42:R42)<>"",SUM(H42:K42)=SUM(O42:R42)) -> FALSE | Z42: =L42=S42 -> TRUE
A43: 부산광역시 | B43: 4 | C43: 20 | D43: 7 | E43: 3 | F43: 11 | G43: 45 | H43: 2 | I43: 5 | J43: 2 | K43: 1 | L43: 3 | M43: 13 | N43: 58 | P43: 2 | Q43: 1 | R43: 1 | S43: 1 | T43: 5 | U43: 1 | V43: 1 | W43: 6 | X43: 64 | Y43: =IF(SUM(O43:R43)<>"",SUM(H43:K43)=SUM(O43:R43)) -> FALSE | Z43: =L43=S43 -> FALSE
...

Sheet 조사불가목록
A1: 개발지역
A2: 경작지
A3: 군사보호구역
A4: 무립목지
A5: 분류오류
A6: 수계
A7: 옥상
A8: 조경수농장
A9: 출입금지
A10: 협조불가

Sheet NFI지원팀물량
A1: 표본점번호 | B1: 유형 | C1: POINT_X | D1: POINT_Y | E1: 시도 | F1: 시군구 | G1: 읍면동 | H1: 주소 | I1: 조사가능불가 | J1: 조사번호 | K1: 표본점번호 | L1: EPSG4326 | M1: 표고 | N1: 구분 | O1: NFI지원팀
A2: 511047320218 | B2: 가로수 | C2: 1047300 | D2: 2021800 | E2: 강원특별자치도 | F2: 양구군 | G2: 동면 | H2: 강원특별자치도 양구군 동면 임당리 700-2 | I2: #N/A | J2: 양구군_필수_1 | K2: 511047320218 | L2: 38.1952353371, 128.040174089 | M2: 278 | N2: 필수 | O2: 5
A3: 511047420220 | B3: 가로수 | C3: 1047400 | D3: 2022000 | E3: 강원특별자치도 | F3: 양구군 | G3: 동면 | H3: 강원특별자치도 양구군 동면 임당리 623-3 | I3: #N/A | J3: 양구군_필수_2 | K3: 511047420220 | L3: 38.1970325167, 128.0413294028 | M3: 278 | N3: 필수 | O3: 5
A4: 511043120105 | B4: 경관숲 | C4: 1043100 | D4: 2010500 | E4: 강원특별자치도 | F4: 양구군 | G4: 양구읍 | H4: 강원특별자치도 양구군 양구읍 송청리 87-50 | I4: #N/A | J4: 양구군_필수_3 | K4: 511043120105 | L4: 38.0936067083, 127.9915273082 | M4: 188 | N4: 필수 | O4: 5
A5: 511042020109 | B5: 경관숲 | C5: 1042000 | D5: 2010900 | E5: 강원특별자치도 | F5: 양구군 | G5: 양구읍 | H5: 강원특별자치도 양구군 양구읍 정림리 255-1 | I5: #N/A | J5: 양구군_필수_4 | K5: 511042020109 | L5: 38.0972634847, 127.9790064667 | M5: 201 | N5: 필수 | O5: 5
A6: 511042320118 | B6: 경관숲 | C6: 1042300 | D6: 2011800 | E6: 강원특별자치도 | F6: 양구군 | G6: 양구읍 | H6: 강원특별자치도 양구군 양구읍 상리 394 | I6: #N/A | J6: 양구군_필수_5 | K6: 511042320118 | L6: 38.1053606697, 127.9824811649 | M6: 181 | N6: 필수 | O6: 5
A7: 511047520225 | B7: 학교숲 | C7: 1047500 | D7: 2022500 | E7: 강원특별자치도 | F7: 양구군 | G7: 동면 | H7: 강원특별자치도 양구군 동면 임당리 564 | I7: #N/A | J7: 양구군_필수_6 | K7: 511047520225 | L7: 38.2015333401, 128.0425048354 | M7: 295 | N7: 필수 | O7: 5
A8: 511043420142 | B8: 경관숲 | C8: 1043400 | D8: 2014200 | E8: 강원특별자치도 | F8: 양구군 | G8: 양구읍 | H8: 강원특별자치도 양구군 양구읍 하리 639-4 | I8: #N/A | J8: 양구군_필수_7 | K8: 511043420142 | L8: 38.1269382035, 127.995173562 | M8: 184 | N8: 필수 | O8: 5
A9: 511042720111 | B9: 마을숲 | C9: 1042700 | D9: 2011100 | E9: 강원특별자치도 | F9: 양구군 | G9: 양구읍 | H9: 강원특별자치도 양구군 양구읍 상리 609 | I9: #N/A | J9: 양구군_필수_8 | K9: 511042720111 | L9: 38.0990331555, 127.9870016065 | M9: 188 | N9: 필수 | O9: 5
A10: 511043120113 | B10: 학교숲 | C10: 1043100 | D10: 2011300 | E10: 강원특별자치도 | F10: 양구군 | G10: 양구읍 | H10: 강원특별자치도 양구군 양구읍 상리 186-3 | I10: #N/A | J10: 양구군_필수_9 | K10: 511043120113 | L10: 38.1008166428, 127.9915756038 | M10: 188 | N10: 필수 | O10: 5
A11: 511042620125 | B11: 경관숲 | C11: 1042600 | D11: 2012500 | E11: 강원특별자치도 | F11: 양구군 | G11: 양구읍 | H11: 강원특별자치도 양구군 양구읍 하리 118-7 | I11: #N/A | J11: 양구군_필수_10 | K11: 511042620125 | L11: 38.1116552552, 127.9859446959 | M11: 182 | N11: 필수 | O11: 5
A12: 511042720112 | B12: 마을숲 | C12: 1042700 | D12: 2011200 | E12: 강원특별자치도 | F12: 양구군 | G12: 양구읍 | H12: 강원특별자치도 양구군 양구읍 상리 584 | I12: #N/A | J12: 양구군_필수_11 | K12: 511042720112 | L12: 38.0999343976, 127.9870075881 | M12: 187 | N12: 필수 | O12: 5
A13: 511053720284 | B13: 경관숲 | C13: 1053700 | D13: 2028400 | E13: 강원특별자치도 | F13: 양구군 | G13: 해안면 | H13: 강원특별자치도 양구군 해안면 만대리 2641 | I13: #N/A | J13: 양구군_필수_12 | K13: 511053720284 | L13: 38.2543557824, 128.1137591173 | M13: 577 | N13: 필수 | O13: 5
... A55: 511085519092 | B55: 마을숲 | C55: 1085500 | D55: 1909200 | E55: 강원특별자치도 | F55: 영월군 | G55: 영월읍 | H55: 강원특별자치도 영월군 영월읍 하송리 56 | I55: #N/A | J55: 영월군_필수_33 | K55: 511085519092 | L55: 37.177656934, 128.4631657218 | M55: 202 | N55: 필수 | O55: 3
A56: 511119619060 | B56: 가로수 | C56: 1119600 | D56: 1906000 | E56: 강원특별자치도 | F56: 영월군 | G56: 상동읍 | H56: 강원특별자치도 영월군 상동읍 구래리 산1-53 | I56: #N/A | J56: 영월군_예비_1 | K56: 511119619060 | L56: 37.1450748904, 128.8467107333 | M56: 627 | N56: 예비 | O56: 2, 3
A57: 511085119097 | B57: 학교숲 | C57: 1085100 | D57: 1909700 | E57: 강원특별자치도 | F57: 영월군 | G57: 영월읍 | H57: 강원특별자치도 영월군 영월읍 하송리 308-1 | I57: #N/A | J57: 영월군_예비_2 | K57: 511085119097 | L57: 37.1821999194, 128.458717214 | M57: 208 | N57: 예비 | O57: 2, 3
A58: 511083719095 | B58: 경관숲 | C58: 1083700 | D58: 1909500 | E58: 강원특별자치도 | F58: 영월군 | G58: 영월읍 | H58: 강원특별자치도 영월군 영월읍 방절리 254 | I58: #N/A | J58: 영월군_예비_3 | K58: 511083719095 | L58: 37.1805238959, 128.4429246886 | M58: 197 | N58: 예비 | O58: 2, 3
A59: 511086419107 | B59: 마을숲 | C59: 1086400 | D59: 1910700 | E59: 강원특별자치도 | F59: 영월군 | G59: 영월읍 | H59: 강원특별자치도 영월군 영월읍 영흥리 722-16 | I59: #N/A | J59: 영월군_예비_4 | K59: 511086419107 | L59: 37.1910933592, 128.4734764912 | M59: 208 | N59: 예비 | O59: 2, 3
A60: 511068519196 | B60: 마을숲 | C60: 1068500 | D60: 1919600 | E60: 강원특별자치도 | F60: 영월군 | G60: 주천면 | H60: 강원특별자치도 영월군 주천면 주천리 1367-1 | I60: #N/A | J60: 영월군_예비_5 | K60: 511068519196 | L60: 37.2727967855, 128.2726326443 | M60: 252 | N60: 예비 | O60: 2, 3
A61: 511083219093 | B61: 경관숲 | C61: 1083200 | D61: 1909300 | E61: 강원특별자치도 | F61: 영월군 | G61: 영월읍 | H61: 강원특별자치도 영월군 영월읍 방절리 534-2 | I61: #N/A | J61: 영월군_예비_6 | K61: 511083219093 | L61: 37.178765996, 128.4372703412 | M61: 225 | N61: 예비 | O61: 2, 3
A62: 511086919098 | B62: 도시숲 | C62: 1086900 | D62: 1909800 | E62: 강원특별자치도 | F62: 영월군 | G62: 영월읍 | H62: 강원특별자치도 영월군 영월읍 덕포리 490-3 | I62: #N/A | J62: 영월군_예비_7 | K62: 511086919098 | L62: 37.182935396, 128.4790045655 | M62: 194 | N62: 예비 | O62: 2, 3
A63: 511086619090 | B63: 마을숲 | C63: 1086600 | D63: 1909000 | E63: 강원특별자치도 | F63: 영월군 | G63: 영월읍 | H63: 강원특별자치도 영월군 영월읍 덕포리 995 | I63: #N/A | J63: 영월군_예비_8 | K63: 511086619090 | L63: 37.1757529952, 128.4755325205 | M63: 199 | N63: 예비 | O63: 2, 3
A64: 511084119096 | B64: 경관숲 | C64: 1084100 | D64: 1909600 | E64: 강원특별자치도 | F64: 영월군 | G64: 영월읍 | H64: 강원특별자치도 영월군 영월읍 방절리 산38-1 | I64: #N/A | J64: 영월군_예비_9 | K64: 511084119096 | L64: 37.1813892436, 128.4474415968 | M64: 201 | N64: 예비 | O64: 2, 3
A65: 511084219106 | B65: 경관숲 | C65: 1084200 | D65: 1910600 | E65: 강원특별자치도 | F65: 영월군 | G65: 영월읍 | H65: 강원특별자치도 영월군 영월읍 방절리 46-1 | I65: #N/A | J65: 영월군_예비_10 | K65: 511084219106 | L65: 37.1903931382, 128.4486807585 | M65: 204 | N65: 예비 | O65: 2, 3
A66: 511086419093 | B66: 경관숲 | C66: 1086400 | D66: 1909300 | E66: 강원특별자치도 | F66: 영월군 | G66: 영월읍 | H66: 강원특별자치도 영월군 영월읍 덕포리 541-2 | I66: #N/A | J66: 영월군_예비_11 | K66: 511086419093 | L66: 37.1784753778, 128.473314545 | M66: 189 | N66: 예비 | O66: 2, 3
A67: 511073219095 | B67: 마을숲 | C67: 1073200 | D67: 1909500 | E67: 강원특별자치도 | F67: 영월군 | G67: 한반도면 | H67: 강원특별자치도 영월군 한반도면 쌍용리 448-3 | I67: #N/A | J67: 영월군_예비_12 | K67: 511073219095 | L67: 37.1814061618, 128.3246486197 | M67: 239 | N67: 예비 | O67: 2, 3
... A72: 511086819082 | B72: 경관숲 | C72: 1086800 | D72: 1908200 | E72: 강원특별자치도 | F72: 영월군 | G72: 영월읍 | H72: 강원특별자치도 영월군 영월읍 덕포리 951 | I72: #N/A | J72: 영월군_예비_17 | K72: 511086819082 | L72: 37.1685241454, 128.4776922726 | M72: 190 | N72: 예비 | O72: 2, 3
A73: 511041419271 | B73: 가로수 | C73: 1041400 | D73: 1927100 | E73: 강원특별자치도 | F73: 원주시 | G73: 봉산동 | H73: 강원특별자치도 원주시 봉산동 1202 | I73: #N/A | J73: 원주시_필수_1 | K73: 511041419271 | L73: 37.3419995747, 127.9673939528 | M73: 136 | N73: 필수 | O73: 3
A74: 511039819256 | B74: 가로수 | C74: 1039800 | D74: 1925600 | E74: 강원특별자치도 | F74: 원주시 | G74: 단구동 | H74: 강원특별자치도 원주시 단구동 1591-11 | I74: #N/A | J74: 원주시_필수_2 | K74: 511039819256 | L74: 37.3285490976, 127.9492504071 | M74: 178 | N74: 필수 | O74: 3
A75: 511038719272 | B75: 마을숲 | C75: 1038700 | D75: 1927200 | E75: 강원특별자치도 | F75: 원주시 | G75: 단계동 | H75: 강원특별자치도 원주시 단계동 798 | I75: #N/A | J75: 원주시_필수_3 | K75: 511038719272 | L75: 37.343017437, 127.9369177987 | M75: 158 | N75: 필수 | O75: 3
A76: 511027719232 | B76: 경관숲 | C76: 1027700 | D76: 1923200 | E76: 강원특별자치도 | F76: 원주시 | G76: 문막읍 | H76: 강원특별자치도 원주시 문막읍 문막리 924-13 | I76: #N/A | J76: 원주시_필수_4 | K76: 511027719232 | L76: 37.3073557023, 127.8125819178 | M76: 57 | N76: 필수 | O76: 3
A77: 511041619270 | B77: 경관숲 | C77: 1041600 | D77: 1927000 | E77: 강원특별자치도 | F77: 원주시 | G77: 행구동 | H77: 강원특별자치도 원주시 행구동 1817-8 | I77: #N/A | J77: 원주시_필수_5 | K77: 511041619270 | L77: 37.3410892723, 127.9696462124 | M77: 137 | N77: 필수 | O77: 3
A78: 511033519339 | B78: 경관숲 | C78: 1033500 | D78: 1933900 | E78: 강원특별자치도 | F78: 원주시 | G78: 지정면 | H78: 강원특별자치도 원주시 지정면 월송리 12-1 | I78: #N/A | J78: 원주시_필수_6 | K78: 511033519339 | L78: 37.4036112262, 127.8785150882 | M78: 103 | N78: 필수 | O78: 3
A79: 511038619305 | B79: 학교숲 | C79: 1038600 | D79: 1930500 | E79: 강원특별자치도 | F79: 원주시 | G79: 우산동 | H79: 강원특별자치도 원주시 우산동 307-1 | I79: #N/A | J79: 원주시_필수_7 | K79: 511038619305 | L79: 37.3727665551, 127.9359608562 | M79: 129 | N79: 필수 | O79: 3
A80: 511036619292 | B80: 경관숲 | C80: 1036600 | D80: 1929200 | E80: 강원특별자치도 | F80: 원주시 | G80: 호저면 | H80: 강원특별자치도 원주시 호저면 만종리 산74-8 | I80: #N/A | J80: 원주시_필수_8 | K80: 511036619292 | L80: 37.3611299353, 127.9133084818 | M80: 116 | N80: 필수 | O80: 3
A81: 511038419293 | B81: 마을숲 | C81: 1038400 | D81: 1929300 | E81: 강원특별자치도 | F81: 원주시 | G81: 우산동 | H81: 강원특별자치도 원주시 우산동 170 | I81: #N/A | J81: 원주시_필수_9 | K81: 511038419293 | L81: 37.361958527, 127.9336397953 | M81: 134 | N81: 필수 | O81: 3
A82: 511039419283 | B82: 마을숲 | C82: 1039400 | D82: 1928300 | E82: 강원특별자치도 | F82: 원주시 | G82: 학성동 | H82: 강원특별자치도 원주시 학성동 223-26 | I82: #N/A | J82: 원주시_필수_10 | K82: 511039419283 | L82: 37.3529029764, 127.9448789865 | M82: 125 | N82: 필수 | O82: 3
A83: 511041819239 | B83: 마을숲 | C83: 1041800 | D83: 1923900 | E83: 강원특별자치도 | F83: 원주시 | G83: 관설동 | H83: 강원특별자치도 원주시 관설동 1334-4 | I83: #N/A | J83: 원주시_필수_11 | K83: 511041819239 | L83: 37.3131380516, 127.9717293382 | M83: 165 | N83: 필수 | O83: 3
A84: 511040119275 | B84: 도시숲 | C84: 1040100 | D84: 1927500 | E84: 강원특별자치도 | F84: 원주시 | G84: 원동 | H84: 강원특별자치도 원주시 원동 85-3 | I84: #N/A | J84: 원주시_필수_12 | K84: 511040119275 | L84: 37.3456620959, 127.952739402 | M84: 127 | N84: 필수 | O84: 3
... A109: 511062220148 | B109: 경관숲 | C109: 1062200 | D109: 2014800 | E109: 강원특별자치도 | F109: 인제군 | G109: 북면 | H109: 강원특별자치도 인제군 북면 원통리 574-2 | I109: #N/A | J109: 인제군_필수_14 | K109: 511062220148 | L109: 38.1312455292, 128.209712178 | M109: 261 | N109: 필수 | O109: 4
...
